Workbook
Name _: Dados!#REF!
Name __xlfn_CONCAT: NA()
Name __xlfn_COUNTIFS: NA()
Name __xlfn_IFERROR: NA()
Name DADOS: Dados!$A:$W
Name Excel_BuiltIn__FilterDatabase: Dados!$A$1:$W$1
Name FVU: FVU!$B$1:$E$19
Name LAUDO: Laudo!$R$1
Name LOCAL: Tabelas!$B$1:$F$42
Name MEDIDA: Tabelas!$H$1:$J$31
Name Print_Area: Laudo!$B$1:$S$46
Name RELATOR: Tabelas!$H$33:$J$37
Name Z_DE77BDAE_AAB9_4162_893C_9BE3B04FC21D__wvu_Cols: (Laudo!#REF!,Laudo!$I:$J,Laudo!$M:$N)
Name Z_DE77BDAE_AAB9_4162_893C_9BE3B04FC21D__wvu_Cols: 'RESUMO MENSAL'!$A:$A
Name Z_DE77BDAE_AAB9_4162_893C_9BE3B04FC21D__wvu_FilterData: Dados!$A$1:$W$207
Name Z_DE77BDAE_AAB9_4162_893C_9BE3B04FC21D__wvu_Rows: (Laudo!#REF!,Laudo!$43:$43)
Name Z_DE77BDAE_AAB9_4162_893C_9BE3B04FC21D__wvu_Rows: 'RESUMO MENSAL'!$1:$1

Sheet Tabelas
B1: CONTROLE DE PNEUS | H1: Listagem medidas de pneus
B2: MOVIMENTAÇÕES | H2: Código | I2: Descrição | J2: Valor
B3: LOCAL | C3: ALMOXARIFADO | D3: EMPRESA | E3: FILIAL | F3: GARAGEM | H3: 1 | I3: 295/80R22.5 | J3: 650
B4: 98 | C4: ANA LUCIA | D4: 4 | E4: 24 | F4: 17 | H4: 2 | I4: 275/80R22.5 | J4: 600
B5: 57 | C5: BRUMADINHO | D5: 4 | E5: 11 | F5: 2 | H5: 3 | I5: 11.00 R 22 | J5: 400
B6: 18 | C6: CAETE | D6: 1 | E6: 27 | F6: 3 | H6: 4 | I6: 215/75R17.5 | J6: 450
B7: 15 | C7: CAPELINHA | D7: 1 | E7: 30 | F7: 21 | H7: 5 | I7: 10.00 R 20 | J7: 350
B8: 35 | C8: CARMESIA | D8: 1 | E8: 15 | F8: 4 | H8: 6 | I8: 7.50 R16 | J8: 200
B9: 33 | C9: CEL FABRICIANO | D9: 2 | E9: 4 | F9: 46 | H9: 7 | I9: 11 R 22.5 | J9: 350
B10: 40 | C10: DUVAL DE BARROS | D10: 4 | E10: 1 | F10: 5 | H10: 8 | I10: 225/70R15 | J10: 100
B11: 220 | C11: GOIANIA | D11: 34 | E11: 1 | F11: 59 | H11: 9 | I11: 175/70R13 | J11: 100
B12: 12 | C12: GUANHAES | D12: 1 | E12: 18 | F12: 6 | H12: 10 | I12: 165/70R13 | J12: 100
B13: 28 | C13: IPATINGA | D13: 1 | E13: 33 | F13: 7 | H13: 11 | I13: 70/100R19 | J13: 100
B14: 4 | C14: ITABIRA | D14: 1 | E14: 10 | F14: 8 | H14: 12 | I14: 90/100R16 | J14: 100
B15: 55 | C15: ITAUNA | D15: 4 | E15: 9 | F15: 9 | H15: 13 | I15: 175/65R14 | J15: 100
... B28: 52 | C28: NOVA LIMA | D28: 4 | E28: 21 | F28: 91 | H28: 33 | I28: 195/55 R16 | J28: 100
B29: 30 | C29: NOVA VISTA | D29: 34 | E29: 5 | H29: 34 | I29: 185/60R15 | J29: 100
B30: 13 | C30: OLIVEIRA | D30: 1 | E30: 11 | F30: 15 | H30: 35 | I30: 225/75 R15 | J30: 100
B31: 2 | C31: PNEUS | D31: 1 | E31: 1 | F31: 1 | H31: 36 | I31: 205/70R15 | J31: 100
B32: 75 | C32: SALINAS | D32: 31 | E32: 4 | F32: 116
B33: 61 | C33: SARZEDO | D33: 4 | E33: 15 | F33: 16 | H33: RG: | I33: NOME
B34: 360 | C34: SETE LAGOAS | D34: 1 | E34: 26 | F34: 18 | H34: 2987 | I34: CAUA RAYLANDER
B35: 27 | C35: TIMOTEO | D35: 2 | E35: 3 | F35: 23 | H35: 13970 | I35: Natália B. Santos
B36: 71 | C36: TRANSNORTE CARGAS | D36: 30 | E36: 2 | F36: 112 | H36: 16196 | I36: Everson Veloso
B37: 70 | C37: TRANSNORTE M. CLAROS | D37: 31 | E37: 1 | F37: 111 | H37: 2631 | I37: Andre D' Cezari
B38: 72 | C38: TRANSNORTE PEDRO II | D38: 30 | E38: 3 | F38: 113
B39: 56 | C39: UBERLANDIA | D39: 4 | E39: 10 | F39: 90
B40: 60 | C40: VARGINHA | D40: 4 | E40: 14 | F40: 19
B41: 990 | C41: VENEZA | D41: 1 | E41: 40 | F41: 99
B42: 59 | C42: VESPASIANO | D42: 4 | E42: 13 | F42: 14

Sheet Dados
A1: LAUDO Nº | B1: FOGO | G1: UNIDADE | J1: ANÁLISE | K1: Nº REF. | L1: KM POSIÇÃO | M1: KM TOTAL | N1: VALOR | O1: STATUS | P1: RETORNO | Q1: DESCONTO | R1: FVU | S1: 2262 | T1: CAUSAS PROVAVEIS | U1: COMPLEMENTO | V1: RELATOR | X1: MÊS | Y1: DIAS PENDENTE | Z1: CATEGORIA
A2: 2297 | B2: 23507 | C2: 2 | D2: =IFERROR(VLOOKUP(C2,MEDIDA,2,FALSE),"") -> 275/80R22.5 | E2: 20718 | F2: TDE | G2: 98 | H2: =IFERROR(VLOOKUP(G2,LOCAL,2,FALSE),"") -> ANA LUCIA | I2: 44918 | J2: 44932 | K2: 0 | L2: 7452 | M2: 56385 | N2: =IFERROR(VLOOKUP(C2,MEDIDA,3,FALSE),"") -> 600 | R2: 45F | S2: =IFERROR(VLOOKUP(R2,FVU,2,FALSE),"") -> Feridas acidentais no flanco. | T2: =IFERROR(VLOOKUP(R2,FVU,3,FALSE),"") -> Objetos pontiagudos, pontas de guias, meio-fio. | U2: =IFERROR(VLOOKUP(R2,FVU,4,FALSE),"") -> Impacto lateral proveniente de erro operacional, solicito avaliação de cobrança. | V2: 16196 | W2: =IFERROR(VLOOKUP(V2,RELATOR,2,FALSE),"") -> Everson Veloso
A3: =IF(B3>0,A2+1,"") -> 2298 | B3: 22715 | C3: 2 | D3: =IFERROR(VLOOKUP(C3,MEDIDA,2,FALSE),"") -> 275/80R22.5 | E3: 90370 | F3: TEE | G3: 990 | H3: =IFERROR(VLOOKUP(G3,LOCAL,2,FALSE),"") -> VENEZA | I3: 44919 | J3: 44932 | K3: 1 | L3: 53172 | M3: 162534 | N3: =IFERROR(VLOOKUP(C3,MEDIDA,3,FALSE),"") -> 600 | R3: 70R | S3: =IFERROR(VLOOKUP(R3,FVU,2,FALSE),"") -> Rachadura na zona baixa do talão. | T3: =IFERROR(VLOOKUP(R3,FVU,3,FALSE),"") -> Aquecimento excessivo proveniente de anomalias do sistema de freio, mau posicionamento do pneu sobre o aro/roda, roda em mau estado de conservação, uso excessivo dos freios devido a velocidade incompatível com a via, pressão abaixo do recomendado rodas sujas e/ou em má condições de uso. | U3: =IFERROR(VLOOKUP(R3,FVU,4,FALSE),"") -> Verificar equalização das rodas (diferença de temperatura acima de 5°), efetuar inspeção no veículo (simetria das forquilhas, pressão dos cilindros, regulagem dos freios, folga nos eixos, tambores de freio, lonas e catracas), caso esteja tudo normal verificar a operação do condutor (instrutores). | V3: 16196 | W3: =IFERROR(VLOOKUP(V3,RELATOR,2,FALSE),"") -> Everson Veloso
A4: =IF(B4>0,A3+1,"") -> 2299 | B4: 21814 | C4: 2 | D4: =IFERROR(VLOOKUP(C4,MEDIDA,2,FALSE),"") -> 275/80R22.5 | E4: 90343 | F4: TDI | G4: 990 | H4: =IFERROR(VLOOKUP(G4,LOCAL,2,FALSE),"") -> VENEZA | I4: 45284 | J4: 44932 | K4: 1 | L4: 19444 | M4: 208274 | N4: =IFERROR(VLOOKUP(C4,MEDIDA,3,FALSE),"") -> 600 | R4: 70Q | S4: =IFERROR(VLOOKUP(R4,FVU,2,FALSE),"") -> Alteração na zona baixa do talão. | T4: =IFERROR(VLOOKUP(R4,FVU,3,FALSE),"") -> Aquecimento excessivo proveniente de anomalias do sistema de freio, mau posicionamento do pneu sobre o aro/roda, uso excessivo dos freios devido a velocidade incompatível com a via, pressão abaixo do recomendado rodas sujas e/ou em má condições de uso. | U4: =IFERROR(VLOOKUP(R4,FVU,4,FALSE),"") -> Verificar equalização das rodas (diferença de temperatura acima de 5°), efetuar inspeção no veículo (simetria das forquilhas, pressão dos cilindros, regulagem dos freios, folga nos eixos, tambores de freio, lonas e catracas). Efetuar limpezas e pinturas das rodas, caso esteja tudo normal verificar a operação do condutor (instrutores). | V4: 16196 | W4: =IFERROR(VLOOKUP(V4,RELATOR,2,FALSE),"") -> Everson Veloso
A5: =IF(B5>0,A4+1,"") -> 2300 | B5: 21242 | C5: 2 | D5: =IFERROR(VLOOKUP(C5,MEDIDA,2,FALSE),"") -> 275/80R22.5 | E5: 90351 | F5: TEI | G5: 990 | H5: =IFERROR(VLOOKUP(G5,LOCAL,2,FALSE),"") -> VENEZA | I5: 44916 | J5: 44932 | K5: 1 | L5: 11404 | M5: 235773 | N5: =IFERROR(VLOOKUP(C5,MEDIDA,3,FALSE),"") -> 600 | R5: 70K | S5: =IFERROR(VLOOKUP(R5,FVU,2,FALSE),"") -> Separações no talão e rupturas dos reforços. | T5: =IFERROR(VLOOKUP(R5,FVU,3,FALSE),"") -> Aquecimento excessivo no tambor de freio, utilização com sobrecarga ou baixa pressão, mau posicionamento do pneu sobre o aro/roda, uso excessivo dos freios devido a velocidade incompatível com a via. | U5: =IFERROR(VLOOKUP(R5,FVU,4,FALSE),"") -> Verificar equalização das rodas (diferença de temperatura acima de 5°), efetuar inspeção no veículo (simetria das forquilhas, pressão dos cilindros, regulagem dos freios, folga nos eixos, tambores de freio, lonas e catracas), caso esteja tudo normal verificar a operação do condutor (instrutores). | V5: 16196 | W5: =IFERROR(VLOOKUP(V5,RELATOR,2,FALSE),"") -> Everson Veloso
A6: =IF(B6>0,A5+1,"") -> 2301 | B6: 24679 | C6: 2 | D6: =IFERROR(VLOOKUP(C6,MEDIDA,2,FALSE),"") -> 275/80R22.5 | E6: 7463 | F6: DD | G6: 56 | H6: =IFERROR(VLOOKUP(G6,LOCAL,2,FALSE),"") -> UBERLANDIA | I6: 44914 | J6: 44932 | K6: 0 | L6: 5706 | M6: 45828 | N6: =IFERROR(VLOOKUP(C6,MEDIDA,3,FALSE),"") -> 600 | R6: 45D | S6: =IFERROR(VLOOKUP(R6,FVU,2,FALSE),"") -> Desgaste irregular da Banda de Rodagem. | T6: =IFERROR(VLOOKUP(R6,FVU,3,FALSE),"") -> Folgas nas mangas, cubos, buchas estouradas, veículo desalinhado. | U6: =IFERROR(VLOOKUP(R6,FVU,4,FALSE),"") -> Verificar folgas nas mangas, cubos e eixos, verificar buchas das barras, amortecedores e suspensão em geral, verificar alinhamento do veículo. Orientar o colaborador a efetuar rodízios e "viradas na roda" quando necessário, além de fazer o acompanhamento das profundidades dos sulcos no pneu. | V6: 16196 | W6: =IFERROR(VLOOKUP(V6,RELATOR,2,FALSE),"") -> Everson Veloso
A7: =IF(B7>0,A6+1,"") -> 2302 | B7: 23949 | C7: 2 | D7: =IFERROR(VLOOKUP(C7,MEDIDA,2,FALSE),"") -> 275/80R22.5 | E7: 7517 | F7: DE | G7: 56 | H7: =IFERROR(VLOOKUP(G7,LOCAL,2,FALSE),"") -> UBERLANDIA | I7: 44918 | J7: 44932 | K7: 0 | L7: 6800 | M7: 73089 | N7: =IFERROR(VLOOKUP(C7,MEDIDA,3,FALSE),"") -> 600 | R7: 48D | S7: =IFERROR(VLOOKUP(R7,FVU,2,FALSE),"") -> Desgaste da Banda de Rodagem por utilização extrema. | T7: =IFERROR(VLOOKUP(R7,FVU,3,FALSE),"") -> Roda travada, "calo" no tambor de freio, utilização extrema , excessiva. | U7: =IFERROR(VLOOKUP(R7,FVU,4,FALSE),"") -> Verificar rodas e tambores de freio, verificar negligência do borracheiro e caso procedente efetuar a cobrança. | V7: 16196 | W7: =IFERROR(VLOOKUP(V7,RELATOR,2,FALSE),"") -> Everson Veloso
A8: =IF(B8>0,A7+1,"") -> 2303 | B8: 23377 | C8: 1 | D8: =IFERROR(VLOOKUP(C8,MEDIDA,2,FALSE),"") -> 295/80R22.5 | E8: 7616 | F8: DE | G8: 56 | H8: =IFERROR(VLOOKUP(G8,LOCAL,2,FALSE),"") -> UBERLANDIA | I8: 44915 | J8: 44932 | K8: 0 | L8: 6075 | M8: 65202 | N8: =IFERROR(VLOOKUP(C8,MEDIDA,3,FALSE),"") -> 650 | R8: 52H | S8: =IFERROR(VLOOKUP(R8,FVU,2,FALSE),"") -> Rodagem sem ar ou com flexão importante no flanco. | T8: =IFERROR(VLOOKUP(R8,FVU,3,FALSE),"") -> Perfurações no topo ou flanco, rodas ou aros danificados, rodagem prolongada sem ar ou baixa pressão, desgaste no flanco por atrito com o solo ou entre germinados. | U8: =IFERROR(VLOOKUP(R8,FVU,4,FALSE),"") -> Condutor rodou com o pneu vazio. Solicito avaliação de cobrança. | V8: 16196 | W8: =IFERROR(VLOOKUP(V8,RELATOR,2,FALSE),"") -> Everson Veloso
A9: =IF(B9>0,A8+1,"") -> 2304 | B9: 24574 | C9: 2 | D9: =IFERROR(VLOOKUP(C9,MEDIDA,2,FALSE),"") -> 275/80R22.5 | E9: 7466 | F9: DE | G9: 56 | H9: =IFERROR(VLOOKUP(G9,LOCAL,2,FALSE),"") -> UBERLANDIA | I9: 44919 | J9: 44932 | K9: 0 | L9: 5375 | M9: 71672 | N9: =IFERROR(VLOOKUP(C9,MEDIDA,3,FALSE),"") -> 600 | R9: 45D | S9: =IFERROR(VLOOKUP(R9,FVU,2,FALSE),"") -> Desgaste irregular da Banda de Rodagem. | T9: =IFERROR(VLOOKUP(R9,FVU,3,FALSE),"") -> Folgas nas mangas, cubos, buchas estouradas, veículo desalinhado. | U9: =IFERROR(VLOOKUP(R9,FVU,4,FALSE),"") -> Verificar folgas nas mangas, cubos e eixos, verificar buchas das barras, amortecedores e suspensão em geral, verificar alinhamento do veículo. Orientar o colaborador a efetuar rodízios e "viradas na roda" quando necessário, além de fazer o acompanhamento das profundidades dos sulcos no pneu. | V9: 16196 | W9: =IFERROR(VLOOKUP(V9,RELATOR,2,FALSE),"") -> Everson Veloso
A10: =IF(B10>0,A9+1,"") -> 2305 | B10: 24246 | C10: 1 | D10: =IFERROR(VLOOKUP(C10,MEDIDA,2,FALSE),"") -> 295/80R22.5 | E10: 7610 | F10: TKDE | G10: 56 | H10: =IFERROR(VLOOKUP(G10,LOCAL,2,FALSE),"") -> UBERLANDIA | I10: 44917 | J10: 44932 | K10: 0 | L10: 48389 | M10: 48389 | N10: =IFERROR(VLOOKUP(C10,MEDIDA,3,FALSE),"") -> 650 | R10: 45R | S10: =IFERROR(VLOOKUP(R10,FVU,2,FALSE),"") -> Pneu não ressulcado | T10: =IFERROR(VLOOKUP(R10,FVU,3,FALSE),"") -> Negligência e/ou não realização do serviço de ressulcagem. | U10: =IFERROR(VLOOKUP(R10,FVU,4,FALSE),"") -> Realizar a ressulcagem dos pneus respeitando os procedimentos conforme manual de ressulcagem. | V10: 16196 | W10: =IFERROR(VLOOKUP(V10,RELATOR,2,FALSE),"") -> Everson Veloso
A11: =IF(B11>0,A10+1,"") -> 2306 | B11: 25351 | C11: 2 | D11: =IFERROR(VLOOKUP(C11,MEDIDA,2,FALSE),"") -> 275/80R22.5 | E11: 7327 | F11: DE | G11: 56 | H11: =IFERROR(VLOOKUP(G11,LOCAL,2,FALSE),"") -> UBERLANDIA | I11: 44889 | J11: 44932 | K11: 0 | L11: 16042 | M11: 41528 | N11: =IFERROR(VLOOKUP(C11,MEDIDA,3,FALSE),"") -> 600 | R11: 45D | S11: =IFERROR(VLOOKUP(R11,FVU,2,FALSE),"") -> Desgaste irregular da Banda de Rodagem. | T11: =IFERROR(VLOOKUP(R11,FVU,3,FALSE),"") -> Folgas nas mangas, cubos, buchas estouradas, veículo desalinhado. | U11: =IFERROR(VLOOKUP(R11,FVU,4,FALSE),"") -> Verificar folgas nas mangas, cubos e eixos, verificar buchas das barras, amortecedores e suspensão em geral, verificar alinhamento do veículo. Orientar o colaborador a efetuar rodízios e "viradas na roda" quando necessário, além de fazer o acompanhamento das profundidades dos sulcos no pneu. | V11: 16196 | W11: =IFERROR(VLOOKUP(V11,RELATOR,2,FALSE),"") -> Everson Veloso
A12: =IF(B12>0,A11+1,"") -> 2307 | B12: 24067 | C12: 2 | D12: =IFERROR(VLOOKUP(C12,MEDIDA,2,FALSE),"") -> 275/80R22.5 | E12: 7321 | F12: TEI | G12: 56 | H12: =IFERROR(VLOOKUP(G12,LOCAL,2,FALSE),"") -> UBERLANDIA | I12: 44915 | J12: 44932 | K12: 0 | L12: 10610 | M12: 75910 | N12: =IFERROR(VLOOKUP(C12,MEDIDA,3,FALSE),"") -> 600 | R12: 45R | S12: =IFERROR(VLOOKUP(R12,FVU,2,FALSE),"") -> Pneu não ressulcado | T12: =IFERROR(VLOOKUP(R12,FVU,3,FALSE),"") -> Negligência e/ou não realização do serviço de ressulcagem. | U12: =IFERROR(VLOOKUP(R12,FVU,4,FALSE),"") -> Realizar a ressulcagem dos pneus respeitando os procedimentos conforme manual de ressulcagem. | V12: 16196 | W12: =IFERROR(VLOOKUP(V12,RELATOR,2,FALSE),"") -> Everson Veloso
A13: =IF(B13>0,A12+1,"") -> 2308 | B13: 23702 | C13: 2 | D13: =IFERROR(VLOOKUP(C13,MEDIDA,2,FALSE),"") -> 275/80R22.5 | E13: 7321 | F13: TEE | G13: 56 | H13: =IFERROR(VLOOKUP(G13,LOCAL,2,FALSE),"") -> UBERLANDIA | I13: 44915 | J13: 44932 | K13: 0 | L13: 10610 | M13: 68337 | N13: =IFERROR(VLOOKUP(C13,MEDIDA,3,FALSE),"") -> 600 | R13: 45R | S13: =IFERROR(VLOOKUP(R13,FVU,2,FALSE),"") -> Pneu não ressulcado | T13: =IFERROR(VLOOKUP(R13,FVU,3,FALSE),"") -> Negligência e/ou não realização do serviço de ressulcagem. | U13: =IFERROR(VLOOKUP(R13,FVU,4,FALSE),"") -> Realizar a ressulcagem dos pneus respeitando os procedimentos conforme manual de ressulcagem. | V13: 16196 | W13: =IFERROR(VLOOKUP(V13,RELATOR,2,FALSE),"") -> Everson Veloso
A14: =IF(B14>0,A13+1,"") -> 2309 | B14: 24423 | C14: 2 | D14: =IFERROR(VLOOKUP(C14,MEDIDA,2,FALSE),"") -> 275/80R22.5 | E14: 8417 | F14: DD | G14: 56 | H14: =IFERROR(VLOOKUP(G14,LOCAL,2,FALSE),"") -> UBERLANDIA | I14: 44918 | J14: 44932 | K14: 0 | L14: 26236 | M14: 97020 | N14: =IFERROR(VLOOKUP(C14,MEDIDA,3,FALSE),"") -> 600 | R14: 45D | S14: =IFERROR(VLOOKUP(R14,FVU,2,FALSE),"") -> Desgaste irregular da Banda de Rodagem. | T14: =IFERROR(VLOOKUP(R14,FVU,3,FALSE),"") -> Folgas nas mangas, cubos, buchas estouradas, veículo desalinhado. | U14: =IFERROR(VLOOKUP(R14,FVU,4,FALSE),"") -> Verificar folgas nas mangas, cubos e eixos, verificar buchas das barras, amortecedores e suspensão em geral, verificar alinhamento do veículo. Orientar o colaborador a efetuar rodízios e "viradas na roda" quando necessário, além de fazer o acompanhamento das profundidades dos sulcos no pneu. | V14: 16196 | W14: =IFERROR(VLOOKUP(V14,RELATOR,2,FALSE),"") -> Everson Veloso
... A135: =IF(B135>0,A134+1,"") -> 2430 | B135: 20385 | C135: 2 | D135: =IFERROR(VLOOKUP(C135,MEDIDA,2,FALSE),"") -> 275/80R22.5 | E135: 10645 | F135: TDE | G135: 870 | H135: =IFERROR(VLOOKUP(G135,LOCAL,2,FALSE),"") -> JUSTINOPOLIS | I135: 44966 | J135: 44980 | K135: 2 | L135: 25540 | M135: 158512 | N135: =IFERROR(VLOOKUP(C135,MEDIDA,3,FALSE),"") -> 600 | R135: 45F | S135: =IFERROR(VLOOKUP(R135,FVU,2,FALSE),"") -> Feridas acidentais no flanco. | T135: =IFERROR(VLOOKUP(R135,FVU,3,FALSE),"") -> Objetos pontiagudos, pontas de guias, meio-fio. | U135: =IFERROR(VLOOKUP(R135,FVU,4,FALSE),"") -> Impacto lateral proveniente de erro operacional, solicito avaliação de cobrança. | V135: 16196 | W135: =IFERROR(VLOOKUP(V135,RELATOR,2,FALSE),"") -> Everson Veloso
A136: =IF(B136>0,A135+1,"") -> 2431 | B136: 24679 | C136: 2 | D136: =IFERROR(VLOOKUP(C136,MEDIDA,2,FALSE),"") -> 275/80R22.5 | E136: S20500 | F136: TEE | G136: 870 | H136: =IFERROR(VLOOKUP(G136,LOCAL,2,FALSE),"") -> JUSTINOPOLIS | I136: 44966 | J136: 44980 | K136: 1 | L136: 4901 | M136: 50729 | N136: =IFERROR(VLOOKUP(C136,MEDIDA,3,FALSE),"") -> 600 | R136: 45F | S136: =IFERROR(VLOOKUP(R136,FVU,2,FALSE),"") -> Feridas acidentais no flanco. | T136: =IFERROR(VLOOKUP(R136,FVU,3,FALSE),"") -> Objetos pontiagudos, pontas de guias, meio-fio. | U136: =IFERROR(VLOOKUP(R136,FVU,4,FALSE),"") -> Impacto lateral proveniente de erro operacional, solicito avaliação de cobrança. | V136: 16196 | W136: =IFERROR(VLOOKUP(V136,RELATOR,2,FALSE),"") -> Everson Veloso
A137: =IF(B137>0,A136+1,"") -> 2432 | B137: 24388 | C137: 2 | D137: =IFERROR(VLOOKUP(C137,MEDIDA,2,FALSE),"") -> 275/80R22.5 | E137: 8433 | F137: DD | G137: 56 | H137: =IFERROR(VLOOKUP(G137,LOCAL,2,FALSE),"") -> UBERLANDIA | I137: 44965 | J137: 44980 | K137: 0 | L137: 4288 | M137: 42038 | N137: =IFERROR(VLOOKUP(C137,MEDIDA,3,FALSE),"") -> 600 | R137: 45D | S137: =IFERROR(VLOOKUP(R137,FVU,2,FALSE),"") -> Desgaste irregular da Banda de Rodagem. | T137: =IFERROR(VLOOKUP(R137,FVU,3,FALSE),"") -> Folgas nas mangas, cubos, buchas estouradas, veículo desalinhado. | U137: =IFERROR(VLOOKUP(R137,FVU,4,FALSE),"") -> Verificar folgas nas mangas, cubos e eixos, verificar buchas das barras, amortecedores e suspensão em geral, verificar alinhamento do veículo. Orientar o colaborador a efetuar rodízios e "viradas na roda" quando necessário, além de fazer o acompanhamento das profundidades dos sulcos no pneu. | V137: 16196 | W137: =IFERROR(VLOOKUP(V137,RELATOR,2,FALSE),"") -> Everson Veloso
A138: =IF(B138>0,A137+1,"") -> 2433 | B138: 102528 | C138: 2 | D138: =IFERROR(VLOOKUP(C138,MEDIDA,2,FALSE),"") -> 275/80R22.5 | E138: 25300 | F138: TEE | G138: 61 | H138: =IFERROR(VLOOKUP(G138,LOCAL,2,FALSE),"") -> SARZEDO | I138: 44968 | J138: 44980 | K138: 2 | L138: 4811 | M138: 223742 | N138: =IFERROR(VLOOKUP(C138,MEDIDA,3,FALSE),"") -> 600 | R138: 45F | S138: =IFERROR(VLOOKUP(R138,FVU,2,FALSE),"") -> Feridas acidentais no flanco. | T138: =IFERROR(VLOOKUP(R138,FVU,3,FALSE),"") -> Objetos pontiagudos, pontas de guias, meio-fio. | U138: =IFERROR(VLOOKUP(R138,FVU,4,FALSE),"") -> Impacto lateral proveniente de erro operacional, solicito avaliação de cobrança. | V138: 16196 | W138: =IFERROR(VLOOKUP(V138,RELATOR,2,FALSE),"") -> Everson Veloso
A139: =IF(B139>0,A138+1,"") -> 2434 | B139: 22299 | C139: 2 | D139: =IFERROR(VLOOKUP(C139,MEDIDA,2,FALSE),"") -> 275/80R22.5 | E139: 11200 | F139: TEI | G139: 98 | H139: =IFERROR(VLOOKUP(G139,LOCAL,2,FALSE),"") -> ANA LUCIA | I139: 44968 | J139: 44980 | K139: 2 | L139: 6995 | M139: 180997 | N139: =IFERROR(VLOOKUP(C139,MEDIDA,3,FALSE),"") -> 600 | R139: 71K | S139: =IFERROR(VLOOKUP(R139,FVU,2,FALSE),"") -> Quebra do talão durante a montagem ou desmontagem proveniente de aquecimento excessivo da roda. | T139: =IFERROR(VLOOKUP(R139,FVU,3,FALSE),"") -> Quebra do talão na montagem/desmontagem, utilização de ferramentas não adequadas, força excessiva ou desproporcional na montagem/desmontagem, pneu com talão baquelizado devido a aquecimento da roda ou baixa pressão. | U139: =IFERROR(VLOOKUP(R139,FVU,4,FALSE),"") -> Orientar o colaborador quanto a desmontagem. Verificar equalização das rodas (diferença de temperatura acima de 5°), efetuar inspeção no veículo (simetria das forquilhas, pressão dos cilindros, regulagem dos freios, folga nos eixos, tambores de freio, lonas e catracas).Efetuar limpezas e pinturas das rodas, caso esteja tudo normal verificar a operação do condutor (instrutores). | V139: 16196 | W139: =IFERROR(VLOOKUP(V139,RELATOR,2,FALSE),"") -> Everson Veloso
A140: =IF(B140>0,A139+1,"") -> 2435 | B140: 96413 | C140: 2 | D140: =IFERROR(VLOOKUP(C140,MEDIDA,2,FALSE),"") -> 275/80R22.5 | E140: 11188 | F140: TDI | G140: 98 | H140: =IFERROR(VLOOKUP(G140,LOCAL,2,FALSE),"") -> ANA LUCIA | I140: 44967 | J140: 44980 | K140: 2 | L140: 36367 | M140: 246903 | N140: =IFERROR(VLOOKUP(C140,MEDIDA,3,FALSE),"") -> 600 | R140: 71K | S140: =IFERROR(VLOOKUP(R140,FVU,2,FALSE),"") -> Quebra do talão durante a montagem ou desmontagem proveniente de aquecimento excessivo da roda. | T140: =IFERROR(VLOOKUP(R140,FVU,3,FALSE),"") -> Quebra do talão na montagem/desmontagem, utilização de ferramentas não adequadas, força excessiva ou desproporcional na montagem/desmontagem, pneu com talão baquelizado devido a aquecimento da roda ou baixa pressão. | U140: =IFERROR(VLOOKUP(R140,FVU,4,FALSE),"") -> Orientar o colaborador quanto a desmontagem. Verificar equalização das rodas (diferença de temperatura acima de 5°), efetuar inspeção no veículo (simetria das forquilhas, pressão dos cilindros, regulagem dos freios, folga nos eixos, tambores de freio, lonas e catracas).Efetuar limpezas e pinturas das rodas, caso esteja tudo normal verificar a operação do condutor (instrutores). | V140: 16196 | W140: =IFERROR(VLOOKUP(V140,RELATOR,2,FALSE),"") -> Everson Veloso
A141: =IF(B141>0,A140+1,"") -> 2436 | B141: 24450 | C141: 2 | D141: =IFERROR(VLOOKUP(C141,MEDIDA,2,FALSE),"") -> 275/80R22.5 | E141: 90395 | F141: TEE | G141: 520 | H141: =IFERROR(VLOOKUP(G141,LOCAL,2,FALSE),"") -> NEVES | I141: 44977 | J141: 44985 | K141: 0 | L141: 16301 | M141: 71287 | N141: =IFERROR(VLOOKUP(C141,MEDIDA,3,FALSE),"") -> 600 | R141: 45R | S141: =IFERROR(VLOOKUP(R141,FVU,2,FALSE),"") -> Pneu não ressulcado | T141: =IFERROR(VLOOKUP(R141,FVU,3,FALSE),"") -> Negligência e/ou não realização do serviço de ressulcagem. | U141: =IFERROR(VLOOKUP(R141,FVU,4,FALSE),"") -> Realizar a ressulcagem dos pneus respeitando os procedimentos conforme manual de ressulcagem. | V141: 16196 | W141: =IFERROR(VLOOKUP(V141,RELATOR,2,FALSE),"") -> Everson Veloso
A142: =IF(B142>0,A141+1,"") -> 2437 | B142: 23545 | C142: 2 | D142: =IFERROR(VLOOKUP(C142,MEDIDA,2,FALSE),"") -> 275/80R22.5 | E142: 90390 | F142: TEE | G142: 520 | H142: =IFERROR(VLOOKUP(G142,LOCAL,2,FALSE),"") -> NEVES | I142: 44974 | J142: 44985 | K142: 1 | L142: 14697 | M142: 121920 | N142: =IFERROR(VLOOKUP(C142,MEDIDA,3,FALSE),"") -> 600 | R142: 70Q | S142: =IFERROR(VLOOKUP(R142,FVU,2,FALSE),"") -> Alteração na zona baixa do talão. | T142: =IFERROR(VLOOKUP(R142,FVU,3,FALSE),"") -> Aquecimento excessivo proveniente de anomalias do sistema de freio, mau posicionamento do pneu sobre o aro/roda, uso excessivo dos freios devido a velocidade incompatível com a via, pressão abaixo do recomendado rodas sujas e/ou em má condições de uso. | U142: =IFERROR(VLOOKUP(R142,FVU,4,FALSE),"") -> Verificar equalização das rodas (diferença de temperatura acima de 5°), efetuar inspeção no veículo (simetria das forquilhas, pressão dos cilindros, regulagem dos freios, folga nos eixos, tambores de freio, lonas e catracas). Efetuar limpezas e pinturas das rodas, caso esteja tudo normal verificar a operação do condutor (instrutores). | V142: 16196 | W142: =IFERROR(VLOOKUP(V142,RELATOR,2,FALSE),"") -> Everson Veloso
A143: =IF(B143>0,A142+1,"") -> 2438 | B143: 23799 | C143: 2 | D143: =IFERROR(VLOOKUP(C143,MEDIDA,2,FALSE),"") -> 275/80R22.5 | E143: 10630 | F143: TEI | G143: 870 | H143: =IFERROR(VLOOKUP(G143,LOCAL,2,FALSE),"") -> JUSTINOPOLIS | I143: 44976 | J143: 44985 | K143: 0 | L143: 2496 | M143: 82889 | N143: =IFERROR(VLOOKUP(C143,MEDIDA,3,FALSE),"") -> 600 | R143: 48D | S143: =IFERROR(VLOOKUP(R143,FVU,2,FALSE),"") -> Desgaste da Banda de Rodagem por utilização extrema. | T143: =IFERROR(VLOOKUP(R143,FVU,3,FALSE),"") -> Roda travada, "calo" no tambor de freio, utilização extrema , excessiva. | U143: =IFERROR(VLOOKUP(R143,FVU,4,FALSE),"") -> Verificar rodas e tambores de freio, verificar negligência do borracheiro e caso procedente efetuar a cobrança. | V143: 16196 | W143: =IFERROR(VLOOKUP(V143,RELATOR,2,FALSE),"") -> Everson Veloso
A144: =IF(B144>0,A143+1,"") -> 2439 | B144: 22210 | C144: 2 | D144: =IFERROR(VLOOKUP(C144,MEDIDA,2,FALSE),"") -> 275/80R22.5 | E144: 11154 | F144: TEI | G144: 870 | H144: =IFERROR(VLOOKUP(G144,LOCAL,2,FALSE),"") -> JUSTINOPOLIS | I144: 44975 | J144: 44985 | K144: 2 | L144: 6407 | M144: 144136 | N144: =IFERROR(VLOOKUP(C144,MEDIDA,3,FALSE),"") -> 600 | R144: 70J | S144: =IFERROR(VLOOKUP(R144,FVU,2,FALSE),"") -> Desenrolamento do retorno da lona carcaça no talão. | T144: =IFERROR(VLOOKUP(R144,FVU,3,FALSE),"") -> Aquecimento no talão ocasionado pelo uso excessivo do freio, má regulagem dos freios, uso excessivo dos freios devido a velocidade incompatível com a via,rodas sujas e/ou em má condições de uso, etc. | U144: =IFERROR(VLOOKUP(R144,FVU,4,FALSE),"") -> Verificar equalização das rodas (diferença de temperatura acima de 5°), efetuar inspeção no veículo (simetria das forquilhas, pressão dos cilindros, regulagem dos freios, folga nos eixos, tambores de freio, lonas e catracas),Efetuar limpezas e pinturas das rodas, caso esteja tudo normal verificar a operação do condutor (instrutores). | V144: 16196 | W144: =IFERROR(VLOOKUP(V144,RELATOR,2,FALSE),"") -> Everson Veloso
A145: =IF(B145>0,A144+1,"") -> 2440 | B145: 24701 | C145: 2 | D145: =IFERROR(VLOOKUP(C145,MEDIDA,2,FALSE),"") -> 275/80R22.5 | E145: 20722 | F145: TEI | G145: 870 | H145: =IFERROR(VLOOKUP(G145,LOCAL,2,FALSE),"") -> JUSTINOPOLIS | I145: 44978 | J145: 44985 | K145: 1 | L145: 9491 | M145: 49258 | N145: =IFERROR(VLOOKUP(C145,MEDIDA,3,FALSE),"") -> 600 | R145: 70J | S145: =IFERROR(VLOOKUP(R145,FVU,2,FALSE),"") -> Desenrolamento do retorno da lona carcaça no talão. | T145: =IFERROR(VLOOKUP(R145,FVU,3,FALSE),"") -> Aquecimento no talão ocasionado pelo uso excessivo do freio, má regulagem dos freios, uso excessivo dos freios devido a velocidade incompatível com a via,rodas sujas e/ou em má condições de uso, etc. | U145: =IFERROR(VLOOKUP(R145,FVU,4,FALSE),"") -> Verificar equalização das rodas (diferença de temperatura acima de 5°), efetuar inspeção no veículo (simetria das forquilhas, pressão dos cilindros, regulagem dos freios, folga nos eixos, tambores de freio, lonas e catracas),Efetuar limpezas e pinturas das rodas, caso esteja tudo normal verificar a operação do condutor (instrutores). | V145: 16196 | W145: =IFERROR(VLOOKUP(V145,RELATOR,2,FALSE),"") -> Everson Veloso
A146: =IF(B146>0,A145+1,"") -> 2441 | B146: 20245 | C146: 2 | D146: =IFERROR(VLOOKUP(C146,MEDIDA,2,FALSE),"") -> 275/80R22.5 | E146: 90298 | F146: TEI | G146: 520 | H146: =IFERROR(VLOOKUP(G146,LOCAL,2,FALSE),"") -> NEVES | I146: 44974 | J146: 44985 | K146: 1 | L146: 194 | M146: 165228 | N146: =IFERROR(VLOOKUP(C146,MEDIDA,3,FALSE),"") -> 600 | R146: 70J | S146: =IFERROR(VLOOKUP(R146,FVU,2,FALSE),"") -> Desenrolamento do retorno da lona carcaça no talão. | T146: =IFERROR(VLOOKUP(R146,FVU,3,FALSE),"") -> Aquecimento no talão ocasionado pelo uso excessivo do freio, má regulagem dos freios, uso excessivo dos freios devido a velocidade incompatível com a via,rodas sujas e/ou em má condições de uso, etc. | U146: =IFERROR(VLOOKUP(R146,FVU,4,FALSE),"") -> Verificar equalização das rodas (diferença de temperatura acima de 5°), efetuar inspeção no veículo (simetria das forquilhas, pressão dos cilindros, regulagem dos freios, folga nos eixos, tambores de freio, lonas e catracas),Efetuar limpezas e pinturas das rodas, caso esteja tudo normal verificar a operação do condutor (instrutores). | V146: 16196 | W146: =IFERROR(VLOOKUP(V146,RELATOR,2,FALSE),"") -> Everson Veloso
A147: =IF(B147>0,A146+1,"") -> 2442 | B147: 24801 | C147: 2 | D147: =IFERROR(VLOOKUP(C147,MEDIDA,2,FALSE),"") -> 275/80R22.5 | E147: 90404 | F147: DE | G147: 990 | H147: =IFERROR(VLOOKUP(G147,LOCAL,2,FALSE),"") -> VENEZA | I147: 44975 | J147: 44985 | K147: 0 | L147: 31218 | M147: 130815 | N147: =IFERROR(VLOOKUP(C147,MEDIDA,3,FALSE),"") -> 600 | R147: 52H | S147: =IFERROR(VLOOKUP(R147,FVU,2,FALSE),"") -> Rodagem sem ar ou com flexão importante no flanco. | T147: =IFERROR(VLOOKUP(R147,FVU,3,FALSE),"") -> Perfurações no topo ou flanco, rodas ou aros danificados, rodagem prolongada sem ar ou baixa pressão, desgaste no flanco por atrito com o solo ou entre germinados. | U147: =IFERROR(VLOOKUP(R147,FVU,4,FALSE),"") -> Condutor rodou com o pneu vazio. Solicito avaliação de cobrança. | V147: 16196 | W147: =IFERROR(VLOOKUP(V147,RELATOR,2,FALSE),"") -> Everson Veloso
A148: =IF(B148>0,A147+1,"") -> 2443 | B148: 25546 | C148: 4 | D148: =IFERROR(VLOOKUP(C148,MEDIDA,2,FALSE),"") -> 215/75R17.5 | E148: 40897 | F148: TDI | G148: 98 | H148: =IFERROR(VLOOKUP(G148,LOCAL,2,FALSE),"") -> ANA LUCIA | I148: 44979 | J148: 44985 | K148: 2 | L148: 188 | M148: 20026 | N148: =IFERROR(VLOOKUP(C148,MEDIDA,3,FALSE),"") -> 450 | R148: 48D | S148: =IFERROR(VLOOKUP(R148,FVU,2,FALSE),"") -> Desgaste da Banda de Rodagem por utilização extrema. | T148: =IFERROR(VLOOKUP(R148,FVU,3,FALSE),"") -> Roda travada, "calo" no tambor de freio, utilização extrema , excessiva. | U148: =IFERROR(VLOOKUP(R148,FVU,4,FALSE),"") -> Verificar rodas e tambores de freio, verificar negligência do borracheiro e caso procedente efetuar a cobrança. | V148: 16196 | W148: =IFERROR(VLOOKUP(V148,RELATOR,2,FALSE),"") -> Everson Veloso
... A171: =IF(B171>0,A170+1,"") -> 2466 | B171: 21217 | C171: 2 | D171: =IFERROR(VLOOKUP(C171,MEDIDA,2,FALSE),"") -> 275/80R22.5 | E171: 90208 | F171: TDI | G171: 520 | H171: =IFERROR(VLOOKUP(G171,LOCAL,2,FALSE),"") -> NEVES | I171: 44988 | J171: 45008 | K171: 1 | L171: 16412 | M171: 145441 | N171: =IFERROR(VLOOKUP(C171,MEDIDA,3,FALSE),"") -> 600 | R171: 70R | S171: =IFERROR(VLOOKUP(R171,FVU,2,FALSE),"") -> Rachadura na zona baixa do talão. | T171: =IFERROR(VLOOKUP(R171,FVU,3,FALSE),"") -> Aquecimento excessivo proveniente de anomalias do sistema de freio, mau posicionamento do pneu sobre o aro/roda, roda em mau estado de conservação, uso excessivo dos freios devido a velocidade incompatível com a via, pressão abaixo do recomendado rodas sujas e/ou em má condições de uso. | U171: =IFERROR(VLOOKUP(R171,FVU,4,FALSE),"") -> Verificar equalização das rodas (diferença de temperatura acima de 5°), efetuar inspeção no veículo (simetria das forquilhas, pressão dos cilindros, regulagem dos freios, folga nos eixos, tambores de freio, lonas e catracas), caso esteja tudo normal verificar a operação do condutor (instrutores). | V171: 16196 | W171: =IFERROR(VLOOKUP(V171,RELATOR,2,FALSE),"") -> Everson Veloso
A172: =IF(B172>0,A171+1,"") -> 2467 | B172: 20614 | C172: 2 | D172: =IFERROR(VLOOKUP(C172,MEDIDA,2,FALSE),"") -> 275/80R22.5 | E172: S20500 | F172: TDI | G172: 870 | H172: =IFERROR(VLOOKUP(G172,LOCAL,2,FALSE),"") -> JUSTINOPOLIS | I172: 44986 | J172: 45008 | K172: 2 | L172: 9607 | M172: 201594 | N172: =IFERROR(VLOOKUP(C172,MEDIDA,3,FALSE),"") -> 600 | R172: 70J | S172: =IFERROR(VLOOKUP(R172,FVU,2,FALSE),"") -> Desenrolamento do retorno da lona carcaça no talão. | T172: =IFERROR(VLOOKUP(R172,FVU,3,FALSE),"") -> Aquecimento no talão ocasionado pelo uso excessivo do freio, má regulagem dos freios, uso excessivo dos freios devido a velocidade incompatível com a via,rodas sujas e/ou em má condições de uso, etc. | U172: =IFERROR(VLOOKUP(R172,FVU,4,FALSE),"") -> Verificar equalização das rodas (diferença de temperatura acima de 5°), efetuar inspeção no veículo (simetria das forquilhas, pressão dos cilindros, regulagem dos freios, folga nos eixos, tambores de freio, lonas e catracas),Efetuar limpezas e pinturas das rodas, caso esteja tudo normal verificar a operação do condutor (instrutores). | V172: 16196 | W172: =IFERROR(VLOOKUP(V172,RELATOR,2,FALSE),"") -> Everson Veloso
A173: =IF(B173>0,A172+1,"") -> 2468 | B173: 22536 | C173: 2 | D173: =IFERROR(VLOOKUP(C173,MEDIDA,2,FALSE),"") -> 275/80R22.5 | E173: 90298 | F173: TEE | G173: 520 | H173: =IFERROR(VLOOKUP(G173,LOCAL,2,FALSE),"") -> NEVES | I173: 44994 | J173: 45008 | K173: 1 | L173: 6311 | M173: 180078 | N173: =IFERROR(VLOOKUP(C173,MEDIDA,3,FALSE),"") -> 600 | R173: 45F | S173: =IFERROR(VLOOKUP(R173,FVU,2,FALSE),"") -> Feridas acidentais no flanco. | T173: =IFERROR(VLOOKUP(R173,FVU,3,FALSE),"") -> Objetos pontiagudos, pontas de guias, meio-fio. | U173: =IFERROR(VLOOKUP(R173,FVU,4,FALSE),"") -> Impacto lateral proveniente de erro operacional, solicito avaliação de cobrança. | V173: 16196 | W173: =IFERROR(VLOOKUP(V173,RELATOR,2,FALSE),"") -> Everson Veloso
A174: =IF(B174>0,A173+1,"") -> 2469 | B174: 25172 | C174: 2 | D174: =IFERROR(VLOOKUP(C174,MEDIDA,2,FALSE),"") -> 275/80R22.5 | E174: 7324 | F174: TEI | G174: 56 | H174: =IFERROR(VLOOKUP(G174,LOCAL,2,FALSE),"") -> UBERLANDIA | I174: 44988 | J174: 45008 | K174: 0 | L174: 10088 | M174: 48932 | N174: =IFERROR(VLOOKUP(C174,MEDIDA,3,FALSE),"") -> 600 | R174: 45R | S174: =IFERROR(VLOOKUP(R174,FVU,2,FALSE),"") -> Pneu não ressulcado | T174: =IFERROR(VLOOKUP(R174,FVU,3,FALSE),"") -> Negligência e/ou não realização do serviço de ressulcagem. | U174: =IFERROR(VLOOKUP(R174,FVU,4,FALSE),"") -> Realizar a ressulcagem dos pneus respeitando os procedimentos conforme manual de ressulcagem. | V174: 16196 | W174: =IFERROR(VLOOKUP(V174,RELATOR,2,FALSE),"") -> Everson Veloso
A175: =IF(B175>0,A174+1,"") -> 2470 | B175: 24237 | C175: 1 | D175: =IFERROR(VLOOKUP(C175,MEDIDA,2,FALSE),"") -> 295/80R22.5 | E175: 7610 | F175: TKEI | G175: 56 | H175: =IFERROR(VLOOKUP(G175,LOCAL,2,FALSE),"") -> UBERLANDIA | I175: 44988 | J175: 45008 | K175: 0 | L175: 7308 | M175: 56679 | N175: =IFERROR(VLOOKUP(C175,MEDIDA,3,FALSE),"") -> 650 | R175: 45R | S175: =IFERROR(VLOOKUP(R175,FVU,2,FALSE),"") -> Pneu não ressulcado | T175: =IFERROR(VLOOKUP(R175,FVU,3,FALSE),"") -> Negligência e/ou não realização do serviço de ressulcagem. | U175: =IFERROR(VLOOKUP(R175,FVU,4,FALSE),"") -> Realizar a ressulcagem dos pneus respeitando os procedimentos conforme manual de ressulcagem. | V175: 16196 | W175: =IFERROR(VLOOKUP(V175,RELATOR,2,FALSE),"") -> Everson Veloso
A176: =IF(B176>0,A175+1,"") -> 2471 | B176: 22756 | C176: 1 | D176: =IFERROR(VLOOKUP(C176,MEDIDA,2,FALSE),"") -> 295/80R22.5 | E176: 7611 | F176: TKDE | G176: 56 | H176: =IFERROR(VLOOKUP(G176,LOCAL,2,FALSE),"") -> UBERLANDIA | I176: 44993 | J176: 45008 | K176: 0 | L176: 10474 | M176: 117433 | N176: =IFERROR(VLOOKUP(C176,MEDIDA,3,FALSE),"") -> 650 | R176: 71J | S176: =IFERROR(VLOOKUP(R176,FVU,2,FALSE),"") -> Agressões durante a montagem ou desmontagem. | T176: =IFERROR(VLOOKUP(R176,FVU,3,FALSE),"") -> Cortes provocados por ferramentas ou máquinas de montagem/desmontagem, utilização de ferramentas não adequadas, força excessiva ou desproporcional na montagem/desmontagem. | U176: =IFERROR(VLOOKUP(R176,FVU,4,FALSE),"") -> Falha na desmontagem do pneu. Solicito avaliação de cobrança. | V176: 16196 | W176: =IFERROR(VLOOKUP(V176,RELATOR,2,FALSE),"") -> Everson Veloso
A177: =IF(B177>0,A176+1,"") -> 2472 | B177: 22756 | C177: 1 | D177: =IFERROR(VLOOKUP(C177,MEDIDA,2,FALSE),"") -> 295/80R22.5 | E177: 7611 | F177: TKDE | G177: 56 | H177: =IFERROR(VLOOKUP(G177,LOCAL,2,FALSE),"") -> UBERLANDIA | I177: 44993 | J177: 45008 | K177: 0 | L177: 10474 | M177: 117433 | N177: =IFERROR(VLOOKUP(C177,MEDIDA,3,FALSE),"") -> 650 | R177: 45D | S177: =IFERROR(VLOOKUP(R177,FVU,2,FALSE),"") -> Desgaste irregular da Banda de Rodagem. | T177: =IFERROR(VLOOKUP(R177,FVU,3,FALSE),"") -> Folgas nas mangas, cubos, buchas estouradas, veículo desalinhado. | U177: =IFERROR(VLOOKUP(R177,FVU,4,FALSE),"") -> Verificar folgas nas mangas, cubos e eixos, verificar buchas das barras, amortecedores e suspensão em geral, verificar alinhamento do veículo. Orientar o colaborador a efetuar rodízios e "viradas na roda" quando necessário, além de fazer o acompanhamento das profundidades dos sulcos no pneu. | V177: 16196 | W177: =IFERROR(VLOOKUP(V177,RELATOR,2,FALSE),"") -> Everson Veloso
A178: =IF(B178>0,A177+1,"") -> 2473 | B178: 21157 | C178: 2 | D178: =IFERROR(VLOOKUP(C178,MEDIDA,2,FALSE),"") -> 275/80R22.5 | E178: 8419 | F178: TDI | G178: 56 | H178: =IFERROR(VLOOKUP(G178,LOCAL,2,FALSE),"") -> UBERLANDIA | I178: 44978 | J178: 45008 | K178: 1 | L178: 14322 | M178: 63223 | N178: =IFERROR(VLOOKUP(C178,MEDIDA,3,FALSE),"") -> 600 | R178: 70R | S178: =IFERROR(VLOOKUP(R178,FVU,2,FALSE),"") -> Rachadura na zona baixa do talão. | T178: =IFERROR(VLOOKUP(R178,FVU,3,FALSE),"") -> Aquecimento excessivo proveniente de anomalias do sistema de freio, mau posicionamento do pneu sobre o aro/roda, roda em mau estado de conservação, uso excessivo dos freios devido a velocidade incompatível com a via, pressão abaixo do recomendado rodas sujas e/ou em má condições de uso. | U178: =IFERROR(VLOOKUP(R178,FVU,4,FALSE),"") -> Verificar equalização das rodas (diferença de temperatura acima de 5°), efetuar inspeção no veículo (simetria das forquilhas, pressão dos cilindros, regulagem dos freios, folga nos eixos, tambores de freio, lonas e catracas), caso esteja tudo normal verificar a operação do condutor (instrutores). | V178: 16196 | W178: =IFERROR(VLOOKUP(V178,RELATOR,2,FALSE),"") -> Everson Veloso
A179: =IF(B179>0,A178+1,"") -> 2474 | B179: 24683 | C179: 2 | D179: =IFERROR(VLOOKUP(C179,MEDIDA,2,FALSE),"") -> 275/80R22.5 | E179: 7480 | F179: DE | G179: 56 | H179: =IFERROR(VLOOKUP(G179,LOCAL,2,FALSE),"") -> UBERLANDIA | I179: 44973 | J179: 45008 | K179: 0 | L179: 12309 | M179: 48083 | N179: =IFERROR(VLOOKUP(C179,MEDIDA,3,FALSE),"") -> 600 | R179: 45D | S179: =IFERROR(VLOOKUP(R179,FVU,2,FALSE),"") -> Desgaste irregular da Banda de Rodagem. | T179: =IFERROR(VLOOKUP(R179,FVU,3,FALSE),"") -> Folgas nas mangas, cubos, buchas estouradas, veículo desalinhado. | U179: =IFERROR(VLOOKUP(R179,FVU,4,FALSE),"") -> Verificar folgas nas mangas, cubos e eixos, verificar buchas das barras, amortecedores e suspensão em geral, verificar alinhamento do veículo. Orientar o colaborador a efetuar rodízios e "viradas na roda" quando necessário, além de fazer o acompanhamento das profundidades dos sulcos no pneu. | V179: 16196 | W179: =IFERROR(VLOOKUP(V179,RELATOR,2,FALSE),"") -> Everson Veloso
A180: =IF(B180>0,A179+1,"") -> 2475 | B180: 24695 | C180: 2 | D180: =IFERROR(VLOOKUP(C180,MEDIDA,2,FALSE),"") -> 275/80R22.5 | E180: 8414 | F180: DE | G180: 56 | H180: =IFERROR(VLOOKUP(G180,LOCAL,2,FALSE),"") -> UBERLANDIA | I180: 44992 | J180: 45008 | K180: 0 | L180: 3341 | M180: 60635 | N180: =IFERROR(VLOOKUP(C180,MEDIDA,3,FALSE),"") -> 600 | R180: 45D | S180: =IFERROR(VLOOKUP(R180,FVU,2,FALSE),"") -> Desgaste irregular da Banda de Rodagem. | T180: =IFERROR(VLOOKUP(R180,FVU,3,FALSE),"") -> Folgas nas mangas, cubos, buchas estouradas, veículo desalinhado. | U180: =IFERROR(VLOOKUP(R180,FVU,4,FALSE),"") -> Verificar folgas nas mangas, cubos e eixos, verificar buchas das barras, amortecedores e suspensão em geral, verificar alinhamento do veículo. Orientar o colaborador a efetuar rodízios e "viradas na roda" quando necessário, além de fazer o acompanhamento das profundidades dos sulcos no pneu. | V180: 16196 | W180: =IFERROR(VLOOKUP(V180,RELATOR,2,FALSE),"") -> Everson Veloso
A181: =IF(B181>0,A180+1,"") -> 2476 | B181: 22590 | C181: 1 | D181: =IFERROR(VLOOKUP(C181,MEDIDA,2,FALSE),"") -> 295/80R22.5 | E181: 7610 | F181: TDE | G181: 56 | H181: =IFERROR(VLOOKUP(G181,LOCAL,2,FALSE),"") -> UBERLANDIA | I181: 44988 | J181: 45008 | K181: 0 | L181: 11259 | M181: 100920 | N181: =IFERROR(VLOOKUP(C181,MEDIDA,3,FALSE),"") -> 650 | R181: 45R | S181: =IFERROR(VLOOKUP(R181,FVU,2,FALSE),"") -> Pneu não ressulcado | T181: =IFERROR(VLOOKUP(R181,FVU,3,FALSE),"") -> Negligência e/ou não realização do serviço de ressulcagem. | U181: =IFERROR(VLOOKUP(R181,FVU,4,FALSE),"") -> Realizar a ressulcagem dos pneus respeitando os procedimentos conforme manual de ressulcagem. | V181: 16196 | W181: =IFERROR(VLOOKUP(V181,RELATOR,2,FALSE),"") -> Everson Veloso
A182: =IF(B182>0,A181+1,"") -> 2477 | B182: 21762 | C182: 2 | D182: =IFERROR(VLOOKUP(C182,MEDIDA,2,FALSE),"") -> 275/80R22.5 | E182: 8437 | F182: TDI | G182: 56 | H182: =IFERROR(VLOOKUP(G182,LOCAL,2,FALSE),"") -> UBERLANDIA | I182: 44995 | J182: 45008 | K182: 1 | L182: 7927 | M182: 188054 | N182: =IFERROR(VLOOKUP(C182,MEDIDA,3,FALSE),"") -> 600 | R182: 45D | S182: =IFERROR(VLOOKUP(R182,FVU,2,FALSE),"") -> Desgaste irregular da Banda de Rodagem. | T182: =IFERROR(VLOOKUP(R182,FVU,3,FALSE),"") -> Folgas nas mangas, cubos, buchas estouradas, veículo desalinhado. | U182: =IFERROR(VLOOKUP(R182,FVU,4,FALSE),"") -> Verificar folgas nas mangas, cubos e eixos, verificar buchas das barras, amortecedores e suspensão em geral, verificar alinhamento do veículo. Orientar o colaborador a efetuar rodízios e "viradas na roda" quando necessário, além de fazer o acompanhamento das profundidades dos sulcos no pneu. | V182: 16196 | W182: =IFERROR(VLOOKUP(V182,RELATOR,2,FALSE),"") -> Everson Veloso
...

Sheet Laudo
G1: GRUPO EMPRESARIAL COORDENADAS | R1: 5092
B3: UNIDADE: | C3: =VLOOKUP(LAUDO,DADOS,8,FALSE) -> UBERLANDIA | G3: Nº FOGO PNEU: | H3: =VLOOKUP(LAUDO,DADOS,2,FALSE) -> 33828 | O3: DATA DA ANÁLISE: | P3: =VLOOKUP(LAUDO,DADOS,10,FALSE) -> 46170
B4: VEÍCULO: | C4: =VLOOKUP(LAUDO,DADOS,5,FALSE) -> 7328 | G4: MEDIDA PNEU: | H4: =VLOOKUP(LAUDO,DADOS,4,FALSE) -> 275/80R22.5 | O4: VALOR SUGERIDO: | P4: =VLOOKUP(LAUDO,DADOS,14,FALSE) -> 600
B5: POSIÇÃO | C5: =VLOOKUP(LAUDO,DADOS,6,FALSE) -> DE | G5: KM POSIÇÃO: | H5: =VLOOKUP(LAUDO,DADOS,12,FALSE) -> 13813 | O5: VALOR COBRADO:
B6: RETIRADA: | C6: =VLOOKUP(LAUDO,DADOS,9,FALSE) -> 46167 | G6: KM TOTAL: | H6: =VLOOKUP(LAUDO,DADOS,13,FALSE) -> 13813 | O6: Nº REFORMAS: | P6: =VLOOKUP(LAUDO,DADOS,11,FALSE) -> 0
B8: =VLOOKUP(LAUDO,DADOS,19,FALSE) -> Desgaste irregular da Banda de Rodagem.
B9: ="Causas prováveis: "&IF(VLOOKUP(LAUDO,DADOS,19,FALSE)="","",VLOOKUP(LAUDO,DADOS,20,FALSE)) -> Causas prováveis: Folgas nas mangas, cubos, buchas estouradas, veículo desalinhado.
B12: ="Observações: "&IF(VLOOKUP(LAUDO,DADOS,20,FALSE)="","",VLOOKUP(LAUDO,DADOS,21,FALSE)) -> Observações: Verificar folgas nas mangas, cubos e eixos, verificar buchas das barras, amortecedores e suspensão em geral, verificar alinhamento do veículo. Orientar o colaborador a efetuar rodízios e "viradas na roda" quando necessário, além de fazer o acompanhamento das profundidades dos sulcos no pneu.
B15: Laudo relatado por: | D15: =VLOOKUP(LAUDO,DADOS,23,FALSE) -> Everson Veloso
D16: Enc. Borracharia
B25: Visto líder de manutenção:
B45: VISTO GERENTE: | K45: VISTO DIRETORIA:
C2263: 2 | E2263: 90048 | F2263: TDI | G2263: 520 | Q2263: 70Q | U2263: 16196
B3655: 25062 | C3655: 2 | E3655: 10837 | F3655: TEE | G3655: 870 | I3655: 45506 | J3655: 45518 | K3655: 1 | L3655: 24306 | M3655: 124565 | Q3655: 70R | U3655: 16196

Sheet RESUMO
A1: 46063 | B1: ANA LUCIA | C1: JUSTINOPOLIS | D1: LAFAIETE | E1: M.GORETTI | F1: NEVES | G1: SARZEDO | H1: UBERLANDIA | I1: VENEZA | J1: TOTAL POR DANO | L1: TOTAL DE PNEUS
A2: Deterioração do topo por choque. | B2: =COUNTIFS(Dados!$S:$S,$A2,Dados!$J:$J,$A$1,Dados!$H:$H,B$1) -> 0 | C2: =COUNTIFS(Dados!$S:$S,$A2,Dados!$J:$J,$A$1,Dados!$H:$H,C$1) -> 0 | D2: =COUNTIFS(Dados!$S:$S,$A2,Dados!$J:$J,$A$1,Dados!$H:$H,D$1) -> 0 | E2: =COUNTIFS(Dados!$S:$S,$A2,Dados!$J:$J,$A$1,Dados!$H:$H,E$1) -> 0 | F2: =COUNTIFS(Dados!$S:$S,$A2,Dados!$J:$J,$A$1,Dados!$H:$H,F$1) -> 0 | G2: =COUNTIFS(Dados!$S:$S,$A2,Dados!$J:$J,$A$1,Dados!$H:$H,G$1) -> 0 | H2: =COUNTIFS(Dados!$S:$S,$A2,Dados!$J:$J,$A$1,Dados!$H:$H,H$1) -> 0 | I2: =COUNTIFS(Dados!$S:$S,$A2,Dados!$J:$J,$A$1,Dados!$H:$H,I$1) -> 0 | J2: =SUM(B2:I2) -> 0 | L2: =SUM(J2:J19) -> 20
A3: Feridas acidentais no flanco. | B3: =COUNTIFS(Dados!$S:$S,$A3,Dados!$J:$J,$A$1,Dados!$H:$H,B$1) -> 0 | C3: =COUNTIFS(Dados!$S:$S,$A3,Dados!$J:$J,$A$1,Dados!$H:$H,C$1) -> 0 | D3: =COUNTIFS(Dados!$S:$S,$A3,Dados!$J:$J,$A$1,Dados!$H:$H,D$1) -> 0 | E3: =COUNTIFS(Dados!$S:$S,$A3,Dados!$J:$J,$A$1,Dados!$H:$H,E$1) -> 0 | F3: =COUNTIFS(Dados!$S:$S,$A3,Dados!$J:$J,$A$1,Dados!$H:$H,F$1) -> 0 | G3: =COUNTIFS(Dados!$S:$S,$A3,Dados!$J:$J,$A$1,Dados!$H:$H,G$1) -> 0 | H3: =COUNTIFS(Dados!$S:$S,$A3,Dados!$J:$J,$A$1,Dados!$H:$H,H$1) -> 0 | I3: =COUNTIFS(Dados!$S:$S,$A3,Dados!$J:$J,$A$1,Dados!$H:$H,I$1) -> 0 | J3: =SUM(B3:I3) -> 0
A4: Deterioração do flanco por choque. | B4: =COUNTIFS(Dados!$S:$S,$A4,Dados!$J:$J,$A$1,Dados!$H:$H,B$1) -> 0 | C4: =COUNTIFS(Dados!$S:$S,$A4,Dados!$J:$J,$A$1,Dados!$H:$H,C$1) -> 0 | D4: =COUNTIFS(Dados!$S:$S,$A4,Dados!$J:$J,$A$1,Dados!$H:$H,D$1) -> 0 | E4: =COUNTIFS(Dados!$S:$S,$A4,Dados!$J:$J,$A$1,Dados!$H:$H,E$1) -> 0 | F4: =COUNTIFS(Dados!$S:$S,$A4,Dados!$J:$J,$A$1,Dados!$H:$H,F$1) -> 0 | G4: =COUNTIFS(Dados!$S:$S,$A4,Dados!$J:$J,$A$1,Dados!$H:$H,G$1) -> 0 | H4: =COUNTIFS(Dados!$S:$S,$A4,Dados!$J:$J,$A$1,Dados!$H:$H,H$1) -> 0 | I4: =COUNTIFS(Dados!$S:$S,$A4,Dados!$J:$J,$A$1,Dados!$H:$H,I$1) -> 0 | J4: =SUM(B4:I4) -> 0
A5: Pneu ressulcado incorretamente | B5: =COUNTIFS(Dados!$S:$S,$A5,Dados!$J:$J,$A$1,Dados!$H:$H,B$1) -> 0 | C5: =COUNTIFS(Dados!$S:$S,$A5,Dados!$J:$J,$A$1,Dados!$H:$H,C$1) -> 0 | D5: =COUNTIFS(Dados!$S:$S,$A5,Dados!$J:$J,$A$1,Dados!$H:$H,D$1) -> 0 | E5: =COUNTIFS(Dados!$S:$S,$A5,Dados!$J:$J,$A$1,Dados!$H:$H,E$1) -> 0 | F5: =COUNTIFS(Dados!$S:$S,$A5,Dados!$J:$J,$A$1,Dados!$H:$H,F$1) -> 0 | G5: =COUNTIFS(Dados!$S:$S,$A5,Dados!$J:$J,$A$1,Dados!$H:$H,G$1) -> 0 | H5: =COUNTIFS(Dados!$S:$S,$A5,Dados!$J:$J,$A$1,Dados!$H:$H,H$1) -> 0 | I5: =COUNTIFS(Dados!$S:$S,$A5,Dados!$J:$J,$A$1,Dados!$H:$H,I$1) -> 0 | J5: =SUM(B5:I5) -> 0
A6: Pneu não ressulcado | B6: =COUNTIFS(Dados!$S:$S,$A6,Dados!$J:$J,$A$1,Dados!$H:$H,B$1) -> 0 | C6: =COUNTIFS(Dados!$S:$S,$A6,Dados!$J:$J,$A$1,Dados!$H:$H,C$1) -> 0 | D6: =COUNTIFS(Dados!$S:$S,$A6,Dados!$J:$J,$A$1,Dados!$H:$H,D$1) -> 0 | E6: =COUNTIFS(Dados!$S:$S,$A6,Dados!$J:$J,$A$1,Dados!$H:$H,E$1) -> 0 | F6: =COUNTIFS(Dados!$S:$S,$A6,Dados!$J:$J,$A$1,Dados!$H:$H,F$1) -> 0 | G6: =COUNTIFS(Dados!$S:$S,$A6,Dados!$J:$J,$A$1,Dados!$H:$H,G$1) -> 0 | H6: =COUNTIFS(Dados!$S:$S,$A6,Dados!$J:$J,$A$1,Dados!$H:$H,H$1) -> 1 | I6: =COUNTIFS(Dados!$S:$S,$A6,Dados!$J:$J,$A$1,Dados!$H:$H,I$1) -> 0 | J6: =SUM(B6:I6) -> 1
A7: Desgaste irregular da Banda de Rodagem. | B7: =COUNTIFS(Dados!$S:$S,$A7,Dados!$J:$J,$A$1,Dados!$H:$H,B$1) -> 0 | C7: =COUNTIFS(Dados!$S:$S,$A7,Dados!$J:$J,$A$1,Dados!$H:$H,C$1) -> 0 | D7: =COUNTIFS(Dados!$S:$S,$A7,Dados!$J:$J,$A$1,Dados!$H:$H,D$1) -> 0 | E7: =COUNTIFS(Dados!$S:$S,$A7,Dados!$J:$J,$A$1,Dados!$H:$H,E$1) -> 0 | F7: =COUNTIFS(Dados!$S:$S,$A7,Dados!$J:$J,$A$1,Dados!$H:$H,F$1) -> 0 | G7: =COUNTIFS(Dados!$S:$S,$A7,Dados!$J:$J,$A$1,Dados!$H:$H,G$1) -> 0 | H7: =COUNTIFS(Dados!$S:$S,$A7,Dados!$J:$J,$A$1,Dados!$H:$H,H$1) -> 2 | I7: =COUNTIFS(Dados!$S:$S,$A7,Dados!$J:$J,$A$1,Dados!$H:$H,I$1) -> 0 | J7: =SUM(B7:I7) -> 2
A8: Agressões repetidas no flanco. | B8: =COUNTIFS(Dados!$S:$S,$A8,Dados!$J:$J,$A$1,Dados!$H:$H,B$1) -> 0 | C8: =COUNTIFS(Dados!$S:$S,$A8,Dados!$J:$J,$A$1,Dados!$H:$H,C$1) -> 0 | D8: =COUNTIFS(Dados!$S:$S,$A8,Dados!$J:$J,$A$1,Dados!$H:$H,D$1) -> 0 | E8: =COUNTIFS(Dados!$S:$S,$A8,Dados!$J:$J,$A$1,Dados!$H:$H,E$1) -> 0 | F8: =COUNTIFS(Dados!$S:$S,$A8,Dados!$J:$J,$A$1,Dados!$H:$H,F$1) -> 0 | G8: =COUNTIFS(Dados!$S:$S,$A8,Dados!$J:$J,$A$1,Dados!$H:$H,G$1) -> 0 | H8: =COUNTIFS(Dados!$S:$S,$A8,Dados!$J:$J,$A$1,Dados!$H:$H,H$1) -> 0 | I8: =COUNTIFS(Dados!$S:$S,$A8,Dados!$J:$J,$A$1,Dados!$H:$H,I$1) -> 0 | J8: =SUM(B8:I8) -> 0
A9: Desgaste da Banda de Rodagem por utilização extrema. | B9: =COUNTIFS(Dados!$S:$S,$A9,Dados!$J:$J,$A$1,Dados!$H:$H,B$1) -> 0 | C9: =COUNTIFS(Dados!$S:$S,$A9,Dados!$J:$J,$A$1,Dados!$H:$H,C$1) -> 0 | D9: =COUNTIFS(Dados!$S:$S,$A9,Dados!$J:$J,$A$1,Dados!$H:$H,D$1) -> 0 | E9: =COUNTIFS(Dados!$S:$S,$A9,Dados!$J:$J,$A$1,Dados!$H:$H,E$1) -> 0 | F9: =COUNTIFS(Dados!$S:$S,$A9,Dados!$J:$J,$A$1,Dados!$H:$H,F$1) -> 0 | G9: =COUNTIFS(Dados!$S:$S,$A9,Dados!$J:$J,$A$1,Dados!$H:$H,G$1) -> 0 | H9: =COUNTIFS(Dados!$S:$S,$A9,Dados!$J:$J,$A$1,Dados!$H:$H,H$1) -> 2 | I9: =COUNTIFS(Dados!$S:$S,$A9,Dados!$J:$J,$A$1,Dados!$H:$H,I$1) -> 0 | J9: =SUM(B9:I9) -> 2
A10: Flexões importantes no interior. | B10: =COUNTIFS(Dados!$S:$S,$A10,Dados!$J:$J,$A$1,Dados!$H:$H,B$1) -> 0 | C10: =COUNTIFS(Dados!$S:$S,$A10,Dados!$J:$J,$A$1,Dados!$H:$H,C$1) -> 0 | D10: =COUNTIFS(Dados!$S:$S,$A10,Dados!$J:$J,$A$1,Dados!$H:$H,D$1) -> 0 | E10: =COUNTIFS(Dados!$S:$S,$A10,Dados!$J:$J,$A$1,Dados!$H:$H,E$1) -> 0 | F10: =COUNTIFS(Dados!$S:$S,$A10,Dados!$J:$J,$A$1,Dados!$H:$H,F$1) -> 0 | G10: =COUNTIFS(Dados!$S:$S,$A10,Dados!$J:$J,$A$1,Dados!$H:$H,G$1) -> 0 | H10: =COUNTIFS(Dados!$S:$S,$A10,Dados!$J:$J,$A$1,Dados!$H:$H,H$1) -> 0 | I10: =COUNTIFS(Dados!$S:$S,$A10,Dados!$J:$J,$A$1,Dados!$H:$H,I$1) -> 0 | J10: =SUM(B10:I10) -> 0
A11: Rodagem sem ar ou com flexão importante no flanco. | B11: =COUNTIFS(Dados!$S:$S,$A11,Dados!$J:$J,$A$1,Dados!$H:$H,B$1) -> 0 | C11: =COUNTIFS(Dados!$S:$S,$A11,Dados!$J:$J,$A$1,Dados!$H:$H,C$1) -> 0 | D11: =COUNTIFS(Dados!$S:$S,$A11,Dados!$J:$J,$A$1,Dados!$H:$H,D$1) -> 0 | E11: =COUNTIFS(Dados!$S:$S,$A11,Dados!$J:$J,$A$1,Dados!$H:$H,E$1) -> 0 | F11: =COUNTIFS(Dados!$S:$S,$A11,Dados!$J:$J,$A$1,Dados!$H:$H,F$1) -> 0 | G11: =COUNTIFS(Dados!$S:$S,$A11,Dados!$J:$J,$A$1,Dados!$H:$H,G$1) -> 0 | H11: =COUNTIFS(Dados!$S:$S,$A11,Dados!$J:$J,$A$1,Dados!$H:$H,H$1) -> 1 | I11: =COUNTIFS(Dados!$S:$S,$A11,Dados!$J:$J,$A$1,Dados!$H:$H,I$1) -> 0 | J11: =SUM(B11:I11) -> 1
A12: Desenrolamento do retorno da lona carcaça no talão. | B12: =COUNTIFS(Dados!$S:$S,$A12,Dados!$J:$J,$A$1,Dados!$H:$H,B$1) -> 0 | C12: =COUNTIFS(Dados!$S:$S,$A12,Dados!$J:$J,$A$1,Dados!$H:$H,C$1) -> 2 | D12: =COUNTIFS(Dados!$S:$S,$A12,Dados!$J:$J,$A$1,Dados!$H:$H,D$1) -> 0 | E12: =COUNTIFS(Dados!$S:$S,$A12,Dados!$J:$J,$A$1,Dados!$H:$H,E$1) -> 0 | F12: =COUNTIFS(Dados!$S:$S,$A12,Dados!$J:$J,$A$1,Dados!$H:$H,F$1) -> 2 | G12: =COUNTIFS(Dados!$S:$S,$A12,Dados!$J:$J,$A$1,Dados!$H:$H,G$1) -> 0 | H12: =COUNTIFS(Dados!$S:$S,$A12,Dados!$J:$J,$A$1,Dados!$H:$H,H$1) -> 0 | I12: =COUNTIFS(Dados!$S:$S,$A12,Dados!$J:$J,$A$1,Dados!$H:$H,I$1) -> 0 | J12: =SUM(B12:I12) -> 4
A13: Separações no talão e rupturas dos reforços. | B13: =COUNTIFS(Dados!$S:$S,$A13,Dados!$J:$J,$A$1,Dados!$H:$H,B$1) -> 1 | C13: =COUNTIFS(Dados!$S:$S,$A13,Dados!$J:$J,$A$1,Dados!$H:$H,C$1) -> 1 | D13: =COUNTIFS(Dados!$S:$S,$A13,Dados!$J:$J,$A$1,Dados!$H:$H,D$1) -> 0 | E13: =COUNTIFS(Dados!$S:$S,$A13,Dados!$J:$J,$A$1,Dados!$H:$H,E$1) -> 1 | F13: =COUNTIFS(Dados!$S:$S,$A13,Dados!$J:$J,$A$1,Dados!$H:$H,F$1) -> 0 | G13: =COUNTIFS(Dados!$S:$S,$A13,Dados!$J:$J,$A$1,Dados!$H:$H,G$1) -> 0 | H13: =COUNTIFS(Dados!$S:$S,$A13,Dados!$J:$J,$A$1,Dados!$H:$H,H$1) -> 0 | I13: =COUNTIFS(Dados!$S:$S,$A13,Dados!$J:$J,$A$1,Dados!$H:$H,I$1) -> 0 | J13: =SUM(B13:I13) -> 3
A14: Ruptura da lona carcaça no talão. | B14: =COUNTIFS(Dados!$S:$S,$A14,Dados!$J:$J,$A$1,Dados!$H:$H,B$1) -> 0 | C14: =COUNTIFS(Dados!$S:$S,$A14,Dados!$J:$J,$A$1,Dados!$H:$H,C$1) -> 0 | D14: =COUNTIFS(Dados!$S:$S,$A14,Dados!$J:$J,$A$1,Dados!$H:$H,D$1) -> 0 | E14: =COUNTIFS(Dados!$S:$S,$A14,Dados!$J:$J,$A$1,Dados!$H:$H,E$1) -> 0 | F14: =COUNTIFS(Dados!$S:$S,$A14,Dados!$J:$J,$A$1,Dados!$H:$H,F$1) -> 0 | G14: =COUNTIFS(Dados!$S:$S,$A14,Dados!$J:$J,$A$1,Dados!$H:$H,G$1) -> 0 | H14: =COUNTIFS(Dados!$S:$S,$A14,Dados!$J:$J,$A$1,Dados!$H:$H,H$1) -> 0 | I14: =COUNTIFS(Dados!$S:$S,$A14,Dados!$J:$J,$A$1,Dados!$H:$H,I$1) -> 0 | J14: =SUM(B14:I14) -> 0
... A19: Agressões físicas ou químicas. | B19: =COUNTIFS(Dados!$S:$S,$A19,Dados!$J:$J,$A$1,Dados!$H:$H,B$1) -> 0 | C19: =COUNTIFS(Dados!$S:$S,$A19,Dados!$J:$J,$A$1,Dados!$H:$H,C$1) -> 0 | D19: =COUNTIFS(Dados!$S:$S,$A19,Dados!$J:$J,$A$1,Dados!$H:$H,D$1) -> 0 | E19: =COUNTIFS(Dados!$S:$S,$A19,Dados!$J:$J,$A$1,Dados!$H:$H,E$1) -> 0 | F19: =COUNTIFS(Dados!$S:$S,$A19,Dados!$J:$J,$A$1,Dados!$H:$H,F$1) -> 0 | G19: =COUNTIFS(Dados!$S:$S,$A19,Dados!$J:$J,$A$1,Dados!$H:$H,G$1) -> 0 | H19: =COUNTIFS(Dados!$S:$S,$A19,Dados!$J:$J,$A$1,Dados!$H:$H,H$1) -> 0 | I19: =COUNTIFS(Dados!$S:$S,$A19,Dados!$J:$J,$A$1,Dados!$H:$H,I$1) -> 0 | J19: =SUM(B19:I19) -> 0
A20: TOTAL POR GARAGEM | B20: =SUM(B2:B19) -> 1 | C20: =SUM(C2:C19) -> 6 | D20: =SUM(D2:D19) -> 0 | E20: =SUM(E2:E19) -> 1 | F20: =SUM(F2:F19) -> 2 | G20: =SUM(G2:G19) -> 1 | H20: =SUM(H2:H19) -> 9 | I20: =SUM(I2:I19) -> 0 | J20: =SUM(J2:J19) -> 20

Sheet FVU
B1: FVU | C1: DESCRIÇÃO | D1: CAUSA | E1: AÇÃO | F1: CATEGORIA | G1: PESO DO DANO | H1: VALOR NOVO | I1: VALOR R1 | J1: VALOR R2 | K1: KM MÉDIO | L1: CUSTO POR KM
B2: 45B | C2: Deterioração do topo por choque. | D2: Impacto contra obstáculos, excesso de pressão. | E2: Impacto na banda de rodagem proveniente de erro operacional, solicito avaliação de cobrança. | F2: BANDA DE RODAGEM | G2: FATAL | H2: 2053.808 | I2: 623 | J2: 623 | K2: 160000 | L2: =SUM(H2:J2)/K2 -> 0.0206238
B3: 45F | C3: Feridas acidentais no flanco. | D3: Objetos pontiagudos, pontas de guias, meio-fio. | E3: Impacto lateral proveniente de erro operacional, solicito avaliação de cobrança. | F3: FLANCO | G3: FATAL | L3: 0.0114
B4: 45G | C4: Deterioração do flanco por choque. | D4: Choque e/ou beliscões no flanco ocasionado pela passagem em buracos ou durante a subida do meio-fio (calçada), desníveis em cabeceiras e pontes, viadutos etc. | E4: Impacto lateral proveniente de erro operacional, solicito avaliação de cobrança. | F4: FLANCO | G4: FATAL
B5: 45N | C5: Pneu ressulcado incorretamente | D5: Falhas ou não realização dos procedimentos conforme manual de ressulcagem. | E5: Solicito avaliação de cobrança | F5: BANDA DE RODAGEM | G5: PARCIAL
B6: 45R | C6: Pneu não ressulcado | D6: Negligência e/ou não realização do serviço de ressulcagem. | E6: Realizar a ressulcagem dos pneus respeitando os procedimentos conforme manual de ressulcagem. | F6: BANDA DE RODAGEM | G6: PARCIAL
B7: 45D | C7: Desgaste irregular da Banda de Rodagem. | D7: Folgas nas mangas, cubos, buchas estouradas, veículo desalinhado. | E7: Verificar folgas nas mangas, cubos e eixos, verificar buchas das barras, amortecedores e suspensão em geral, verificar alinhamento do veículo. Orientar o colaborador a efetuar rodízios e "viradas na roda" quando necessário, além de fazer o acompanhamento das profundidades dos sulcos no pneu. | F7: BANDA DE RODAGEM | G7: PARCIAL
B8: 46F | C8: Agressões repetidas no flanco. | D8: Raspagem contra meio-fio ou guias, objetos entre pneus germinados, contato com partes fixas do veículo. | E8: Impactos constantes na lateral do pneu proveniente de erro operacional, solicito avaliação de cobrança. | F8: FLANCO | G8: FATAL
B9: 48D | C9: Desgaste da Banda de Rodagem por utilização extrema. | D9: Roda travada, "calo" no tambor de freio, utilização extrema , excessiva. | E9: Verificar rodas e tambores de freio, verificar negligência do borracheiro e caso procedente efetuar a cobrança. | F9: BANDA DE RODAGEM | G9: FATAL
B10: 52B | C10: Flexões importantes no interior. | D10: Sobrecarga e/ou baixa pressão, vazamento de ar pela válvula ou pela roda, perfurações no topo ou flanco. | E10: Conferir e efetuar as calibragens periodicamente conforme tabela. | F10: FLANCO | G10: FATAL
B11: 52H | C11: Rodagem sem ar ou com flexão importante no flanco. | D11: Perfurações no topo ou flanco, rodas ou aros danificados, rodagem prolongada sem ar ou baixa pressão, desgaste no flanco por atrito com o solo ou entre germinados. | E11: Condutor rodou com o pneu vazio. Solicito avaliação de cobrança. | F11: FLANCO | G11: FATAL
B12: 70J | C12: Desenrolamento do retorno da lona carcaça no talão. | D12: Aquecimento no talão ocasionado pelo uso excessivo do freio, má regulagem dos freios, uso excessivo dos freios devido a velocidade incompatível com a via,rodas sujas e/ou em má condições de uso, etc. | E12: Verificar equalização das rodas (diferença de temperatura acima de 5°), efetuar inspeção no veículo (simetria das forquilhas, pressão dos cilindros, regulagem dos freios, folga nos eixos, tambores de freio, lonas e catracas),Efetuar limpezas e pinturas das rodas, caso esteja tudo normal verificar a operação do condutor (instrutores). | F12: TALÃO | G12: FATAL
B13: 70K | C13: Separações no talão e rupturas dos reforços. | D13: Aquecimento excessivo no tambor de freio, utilização com sobrecarga ou baixa pressão, mau posicionamento do pneu sobre o aro/roda, uso excessivo dos freios devido a velocidade incompatível com a via. | E13: Verificar equalização das rodas (diferença de temperatura acima de 5°), efetuar inspeção no veículo (simetria das forquilhas, pressão dos cilindros, regulagem dos freios, folga nos eixos, tambores de freio, lonas e catracas), caso esteja tudo normal verificar a operação do condutor (instrutores). | F13: TALÃO | G13: FATAL
B14: 70L | C14: Ruptura da lona carcaça no talão. | D14: Rodagem com baixa pressão ou sobrecarga, mau posicionamento do pneu sobre o aro/roda, cortes ou feridas provocadas durante a montagem, rodas sujas e/ou em má condições de uso, etc. | E14: Conferir e efetuar as calibragens periodicamente conforme tabela. Efetuar limpezas e pinturas das rodas. | F14: TALÃO | G14: FATAL
B15: 70Q | C15: Alteração na zona baixa do talão. | D15: Aquecimento excessivo proveniente de anomalias do sistema de freio, mau posicionamento do pneu sobre o aro/roda, uso excessivo dos freios devido a velocidade incompatível com a via, pressão abaixo do recomendado rodas sujas e/ou em má condições de uso. | E15: Verificar equalização das rodas (diferença de temperatura acima de 5°), efetuar inspeção no veículo (simetria das forquilhas, pressão dos cilindros, regulagem dos freios, folga nos eixos, tambores de freio, lonas e catracas). Efetuar limpezas e pinturas das rodas, caso esteja tudo normal verificar a operação do condutor (instrutores). | F15: TALÃO | G15: FATAL
... B19: 75A | C19: Agressões físicas ou químicas. | D19: Pneu em contato com hidrocarbonetos (óleo diesel, graxa, gasolina, etc. , pneu exposto a fontes de calor soldas, descargas elétricas etc.). | E19: Verificar origem da contaminação e tomar as atitudes cabíveis. | F19: FLANCO | G19: FATAL

Sheet RESUMO MENSAL
C1: 1 | D1: 2 | E1: 3 | F1: 4 | G1: 5 | H1: 6 | I1: 7 | J1: 8 | K1: 9 | L1: 10 | M1: 11 | N1: 12 | O1: =TODAY() -> 46237 | P1: =MONTH(O1) -> 8 | Q1: =YEAR(O1) -> 2026
B2: LAUDOS PENDENTES | C2: 44927 | D2: 44958 | E2: 44986 | F2: 45017 | G2: 45047 | H2: 45078 | I2: 45108 | J2: 45139 | K2: 45170 | L2: 45200 | M2: 45231 | N2: 45261 | O2: MÊS ATUAL | P2: TOTAL
